Workbook
Name bl_no_h: #REF!
Name Ocean_vessel_voyage_no: #REF!

Sheet Sheet2
F7: TSL
F8: TKM
D12: Week number 20: 12th May -18th May
D13: Week number 21: 19th May -25th May
D14: Week number 22: 26th May -1st June
D15: Week number 23: 2nd June -8th June

Sheet New Releases
A1: PO Number

Sheet FCL+Import
A1: Supplier | B1: Category | C1: PO number | D1: Incoterm | E1: Release date | F1: Days Count | G1: POL | H1: POD | I1: Gross Wt | J1: No of Boxes/Pacakages | K1: Vessel | L1: ETD | M1: ETA | N1: SOB | O1: Pre-alert Date | P1: Posi | Q1: Column1 | R1: Column2 | S1: Column3
A2: Taihua Group | B2: IMPORT | C2: HLBU3334881 | D2: CFR | E2: 16/10/2024 | F2: #VALUE! | G2: MUN | H2: RTM | I2: 16000 | J2: 1x 40'HC / Anlieferung Burghausen 02.12.2024 | K2: Seaspan Ganges | L2: 27.10.2024 | M2: 24.11.2024 | P2: 80-0003-411-00 | Q2: HLF 29200550
A3: Taihua Group | B3: IMPORT | C3: HLBU2182927 | D3: CFR | E3: 16/10/2024 | F3: #VALUE! | G3: MUN | H3: RTM | I3: 16000 | J3: 1x 40'HC / Anlieferung Schkopau 04.12.2024 | K3: Seaspan Ganges | L3: 27.10.2024 | M3: 24.11.2024 | P3: 80-0004-411-00 / 80-0005-411-00 | Q3: HLF 25578990
A4: Danieli | B4: TLL | C4: TSL/52026/2400002408 | D4: FOB | E4: 13/11/2024 | F4: #VALUE! | G4: DLC | H4: NSA | I4: 73366 | J4: 7x 40'FR + 1x 40'HC // NOR019 | K4: Margrete Maersk | L4: 30.11.2024 | M4: 23.12.2024 | O4: 12.12.2024 | P4: 22-0036-412-00 | Q4: SFE24250243
A5: Alpine Metal // RFQ no : 623-24-634 | B5: TLL | C5: TSL/54623/2400002634 Lot-1 | D5: FOB | E5: 14/11/2024 | F5: #VALUE! | G5: ANT | H5: VTZ | I5: 12400 | J5: 3x 40'HC | K5: Hy Singapore | L5: 29.11.2024 | M5: 05.01.2025 | O5: 09.12.2024 | P5: 22-0012-412-00 | Q5: YML FHAM0173685
A6: Reel GmbH | B6: NON-TATA | C6: 2406509 | D6: DAP | E6: 15/11/2024 | F6: #VALUE! | G6: SHA | H6: Sharjah | I6: 8344 | J6: 1x40'GP | K6: SYDNEY BRIDGE | L6: 30/11/2024 | M6: 20/12/2024 | O6: 09.12.2024 | P6: 25-0006-412-00 | Q6: SFE24250250A /B
A7: Puyang Refractories // ST00001123 | B7: TSL | C7: TSL/2200057775 | D7: FOB | E7: 27/11/2024 | F7: #VALUE! | G7: DLC | H7: CCU | I7: 204606 | J7: 8x 20'DV | K7: OOCL AMERICA 176S | L7: 09.12.2024 | M7: 05.01.2025 | O7: 18.12.2024 | P7: 32-0014-412-00 | Q7: SFE24250229 // 032E509264
A8: GVA | B8: NON-TATA | D8: INLAND | E8: 13/11/2024 | F8: #VALUE! | G8: SHA | H8: CCU | I8: 30900 | J8: 1 Slagpot | K8: Atlanta Express | L8: 06.12.2024 | M8: 12.01.2025 | O8: - | P8: 25-0009-502-00
A9: Danieli | B9: TLL | C9: TSL/52026/2400002408 | D9: FOB | E9: 19/11/2024 | F9: #VALUE! | G9: QIN | H9: NSA | I9: 11750 | J9: 1x 40'FR / Ref. NOR023 | K9: X-Press Carina | L9: 09.12.2024 | M9: 30.12.2024 | O9: 17.12.2024 | P9: 22-0040-412-00 | Q9: SFE24250246
A10: SMS Group // RFQ no. 459-17 | B10: TLL | C10: TSL/53459/2400002517 | D10: FOB | E10: 28.06.2024 | F10: #VALUE! | G10: HAM | H10: MUM | I10: 83900 | J10: BB 3+1 | K10: Nowowiejski | L10: 10.12.2024 | M10: 18.01.2025 | O10: 19.12.2024 | P10: 22-0035-412-00 | Q10: CP MDSCP240799
A11: SMS | B11: TLL | C11: TSL/53595/2400002529 - Lot 2b | D11: FOB | E11: 11.10.2024 | F11: #VALUE! | G11: HAM | H11: KTP | I11: 62404 | J11: 2x 40'FR(OH) | K11: MEXICO EXPRESS | L11: 11.12.2024 | M11: 13.01.2025 | O11: 13.12.2024 | P11: 27-0002-412-00 | Q11: Ceekay (HL 35132832)
A12: Reel GmbH | B12: NON-TATA | C12: PD0G01321_29238 | D12: CIF | E12: 45607 | F12: 30 | G12: HAM | H12: CCU | I12: 3600 | J12: 1x20'FR (OW OS) | K12: MEXICO EXPRESS | L12: 45608 | M12: 15/01/2025 | O12: 13.12.2024 | P12: 25-0004-412-00 | Q12: Ceekay 24560130
A13: SEOUL ENGG. (RFQ 229-74) | B13: TLL | C13: TSL/54229/2200056174 | D13: FOB | E13: 18.11.2024 | F13: #VALUE! | G13: PUS | H13: CCU | I13: 6630 | J13: 1X20'GP | K13: SITC OSAKA/2432S | L13: 08.12.2024 | M13: 08.01.2025 | O13: 13.12.2024 | P13: 32-0009-412-00 | Q13: Shipped // pre-alert to be sent // FLGSS2412004 // SITPUCC161089G
A14: Bekaert - Balmer | B14: NON-TATA | C14: 4600003466 - Lot 2 | D14: FOB | E14: 19/11/2024 | F14: #VALUE! | G14: ANT | H14: VTZ | J14: 1x20'DV | K14: Mexico Express | L14: 15.12.2024 | M14: 45992 | O14: 16.12.2024 | P14: 25-0005-412-00 | Q14: YML FHAM0172017
A15: Refra 4 | B15: NON-TATA | C15: Gestellung 02.12.2024 / 7 + 9 | D15: CFR | E15: 10.10.2024 | F15: #VALUE! | G15: ANT | H15: VTZ | I15: 41000 | J15: 2x 20'DV | K15: Mexico Express | L15: 15.12.2024 | M15: 12.01.2025 | O15: 16.12.2024 | P15: 25-0008-412-00 | Q15: YML FHAM0172751
A16: Danieli | B16: TLL | C16: TSL/52026/2400002408 | D16: FOB | E16: 19.11.2024 | F16: #VALUE! | G16: LCB | H16: NSA | J16: 1x 40'FR + 5x 40'HC // Ref. NOR022 | K16: YM INTERACTION | L16: 21.12.2024 | M16: 05.01.2025 | O16: 06.01.2025 | P16: 22-0009-501-00 | Q16: OECL / OOCL
A17: Metallon | B17: TSL | C17: TSL/4413088508 | D17: FOB | E17: 27.11.2024 | F17: #VALUE! | G17: TJN | H17: CCU | J17: 4x 40'OT | K17: MSC TRIESTE V.FY451A | L17: 20.12.2024 | M17: 10.01.2025 | O17: 27.12.2024 | P17: 32-0003-501-00 | Q17: SFE24250256 // MEDUYX322322
A18: Alpine Metal | B18: TLL | C18: TSL/54623/2400002634 Lot-2 | D18: FOB | E18: 21/10/2024 | F18: #VALUE! | G18: ANT | H18: VTZ | I18: 40220 | J18: 1x40'FR(IG), 2x40'FR (OW/OH) | K18: YM FOUNTAIN | L18: 26.12.2024 | M18: 22/01/2025 | O18: 02.01.2025 | P18: 22-0011-501-00 | Q18: Ceekay 15126149
A19: Danieli | B19: TLL | C19: TSL/52026/2400002408 | D19: FOB | E19: 18.11.2024 | F19: #VALUE! | G19: GEN | H19: NSA | J19: 1x 40'HC + 1x 20'DV // NOR015 - 3 | K19: Yantian Express | L19: 25.12.2024 | M19: 29.01.2025 | O19: 31.12.2024 | P19: 22-0012-501-00 | Q19: HLF 27522007
A20: Danieli | B20: TLL | C20: TSL/52026/2400002408 | D20: FOB | E20: 18.11.2024 | F20: #VALUE! | G20: GEN | H20: NSA | J20: 40'HCOT(IG) +40'HCOT(OH270) // NOR015 - 1.2 | K20: Yantian Express | L20: 25.12.2024 | M20: 29.01.2025 | O20: 31.12.2024 | P20: 22-0012-501-00 | Q20: HLF 24903357
A21: Danieli | B21: TLL | C21: TSL/52026/2400002408 | D21: FOB | E21: 18.11.2024 | F21: #VALUE! | G21: GEN | H21: NSA | J21: 6x 40'HC // NOR015 - 1.1 | K21: Yantian Express | L21: 25.12.2024 | M21: 29.01.2025 | O21: 31.12.2024 | P21: 22-0012-501-00 | Q21: HLF 90853739
A22: Danieli | B22: TLL | C22: TSL/52026/2400002408 | D22: FOB | E22: 18.11.2024 | F22: #VALUE! | G22: GEN | H22: NSA | J22: 4x 20'OT(IG) // NOR015 - 2.2 | K22: Yantian Express | L22: 25.12.2024 | M22: 29.01.2025 | O22: 31.12.2024 | P22: 22-0012-501-00 | Q22: HLF 12459407
A23: Danieli | B23: TLL | C23: TSL/52026/2400002408 | D23: FOB | E23: 18.11.2024 | F23: #VALUE! | G23: GEN | H23: NSA | J23: 10x 40'HC // NOR015 - 2.1 | K23: Yantian Express | L23: 25.12.2024 | M23: 29.01.2025 | O23: 31.12.2024 | P23: 22-0012-501-00 | Q23: HLF 31816803
A24: Profine | B24: NON-TATA | D24: CIF | E24: 25/11/2024 | F24: 42 | G24: ANT | H24: NSA | J24: 1x40'HC | K24: MSC JOANNA | L24: 45809 | M24: 45690 | O24: 07.01.2025 | P24: 25-0004-501-00 | Q24: MSC 459HA1255411
A25: CPI Vertex | B25: NON-TATA | C25: NL nach Kilgore | D25: CFR | E25: 16.10.2024 | F25: #VALUE! | G25: ANT | H25: HOU | I25: 25600 | J25: 1x 20'OT(IG) | K25: Lucie Schulte | L25: 24.12.2024 | M25: 18.01.2025 | O25: 06.01.2025 | P25: 25-0008-501-00 | Q25: MSK 247572948
A26: Mack Valves // RFQ no : 813-24-666 | B26: TLL | C26: TSL/54813/2400002666 | D26: FOB | E26: 13.11.2024 | F26: #VALUE! | G26: MEL | H26: VTZ | I26: 2740 | J26: 1x20'DV | K26: CMA CGM Tancredi | L26: 05.01.2025 | M26: 18.02.2025 | O26: 08.01.2025 | P26: 22-0028-501-00 | Q26: HL34146253
A27: Tenova | B27: TLL | C27: TSL/52245/2400002415 | D27: FOB | E27: 19.12.2024 | F27: #VALUE! | G27: GEN | H27: NSA | I27: 3674 | J27: 1x20'DV | K27: Hyundai Mars | L27: 16.01.2025 | M27: 20.02.2025 | O27: 21.01.2025 | P27: 22-0029-501-00 | Q27: HMM HAMA38490100
A28: Rupf ATG Casting | B28: Import | C28: CICU8107408 | D28: CFR | E28: 22/12/2024 | F28: #VALUE! | G28: Zhengzhou | H28: HAM | I28: 10646 | J28: 5 cases | K28: WB2024/12/18 | L28: 22.12.2024 | M28: 18.01.2025 | P28: 80-0002-501-00 | Q28: ZIHWB241218LH201
A29: Reissverschluss18 | B29: Import | C29: TWN24110059 | D29: CFR | E29: 18.11.2024 | F29: #VALUE! | G29: KEE | H29: HAM | I29: 3769 | J29: 45 Pkgs | K29: Ever Ace | L29: 16.11.2024 | M29: 08.01.2025 | P29: 80-0001-501-00 | Q29: LSE-890075
A30: Haeusler | B30: NON-TATA | D30: EXW | E30: 45424 | F30: 52 | G30: ANT | H30: VTZ | J30: 1x20'OT, 1x40'OT | K30: RIO GRANDE EXPRESS | L30: 26/01/2025 | M30: 45780 | O30: 30.01.2025 | P30: 25-0003-502-00 | Q30: HL 24857010
A31: ACRE | B31: TLL | C31: TSL/55394/2400002739 | D31: FOB | E31: 19.09.2024 | F31: #VALUE! | G31: TXZ | H31: MAA | I31: 15650 | J31: 2 BB | K31: STAR TYCHE V.MK2461E | L31: 45484 | M31: 27/11/2024 | O31: 19.11.2024 | P31: 27-0003-411-00 | Q31: BBE24250003 // MK2461ETJCHN04
A32: CHINA SHOUGANG // RFQ No :- 318-08 | B32: TLL | C32: TSL/52318/2200053108 | D32: FOB | E32: 05.12.2024 | F32: #VALUE! | G32: TJN | H32: VIZ | I32: 6400 | J32: 1X20/ 6TONS | K32: TS KAOHSIUNG V.24022S | L32: 26.12.2024 | M32: 26.01.2024 | O32: 30.12.2024 | P32: 32-0007-501-00 | Q32: SFE24250271// 800410284386
A33: HEBEI CHENBANG // RFQ no. 290-51 | B33: TLL | C33: TSL/55290/2200057951 | D33: FOB | E33: 14.12.2024 | F33: #VALUE! | G33: QIN | H33: VTZ | I33: 20350 | J33: 1X40'HQ | K33: TS VANCOUVER V.25001W | L33: 06.01.2025 | M33: 23.01.2025 | O33: 08.01.2025 | P33: 32-0009-501-00 | Q33: SFE24250282 // TAOCB24015397
A34: QINYE // UNDER L/C // CRITICAL | B34: TLL | C34: TSL/55036/2200057503 | D34: FOB | E34: 06.12.2024 | F34: #VALUE! | G34: TJN | H34: VTZ | I34: 3865 | J34: 10.11x20FR | K34: SITC BATANGAS V.2502S | L34: 31.12.2024 | M34: 31.01.2025 | O34: 06.01.2025 | P34: 32-0008-501-00 | Q34: SFE24250280 // SITSTXVZ519593
A35: DANIELI | B35: TLL | C35: TSL/52026/2400002408 - NOR026 | D35: FOB | E35: 45870 | F35: #VALUE! | G35: SHA | H35: NSA | I35: 6930 | J35: 1x 20'DV | K35: ONE REPUTATION | L35: 20.01.2025 | M35: 24.02.2025 | O35: 27.01.2025 | P35: 22-0017-502-00 | Q35: SFE24250324
A36: K-ONE // UNDER LC | B36: TLL | C36: TSL/55387/2400002728 | D36: FOB | E36: 24/12/2024 | F36: 38 | G36: PUS | H36: VTZ | I36: 4710 | J36: 1x40'HC | K36: YM WITNESS | L36: 31/01/2025 | M36: 45660 | O36: 04.02.2025 | P36: 32-0001-502-00 | Q36: FLGSS2501006
A37: DANIELI CORUS // RFQ no : 705/24-649 | B37: TLL | C37: TSL/54705/2400002649 - L1 | D37: FOB | E37: 09.01.2025 | F37: #VALUE! | G37: SHA | H37: CCU | I37: 11200 | J37: 2x40'OT | K37: WAN HAI 516 | L37: 01.02.2025 | M37: 20/02/2025 | P37: 32-0002-502-00 | Q37: SFE24250329
A38: Paulwurth - Balmer | B38: NON-TATA | C38: 4130002679 | D38: FOB | E38: 16/12/2024 | F38: 48 | G38: ANT | H38: NSA | I38: 17453 | J38: 1x40'FR, 1x20'DV | K38: VUNG TAU EXPRESS | L38: 45690 | M38: 45872 | O38: 03.02.2025 | P38: 25-0006-502-00 | Q38: Ceekay HL 31706099
A39: SMS GROUP | B39: TLL | C39: TSL/54763/2400002657 - Lot 1.1 | D39: FOB | E39: 28/01/2025 | F39: #VALUE! | G39: HAM | H39: MUM | I39: 17660 | J39: 3 Pcs / BB | K39: CP Atlantic | L39: 30.01.2025 | M39: 15.03.2025 | O39: 10.02.2025 | P39: 22-0028-502-00 | Q39: CP MDSCP250049
A40: TEAMWELL // ST00001212 | B40: TSL | C40: TSL/2200058898 | D40: FOB | E40: 02.01.2025 | F40: #VALUE! | G40: XIN | H40: CCU | I40: 162900 | J40: 9X20'GP | K40: ISARA BHUM | L40: 45749 | M40: 27/01/2025 | O40: 07.02.2025 | P40: 32-0003-502-00 | Q40: SFE24250308 // TSNCB25000219
...

Sheet FCL+Import Completed
A1: Supplier | B1: Category | C1: PO number | D1: Incoterm | E1: Release date | F1: Days Count | G1: POL | H1: POD | I1: Gross Wt | J1: No of Boxes/Pacakages | K1: Remarks | L1: ETD | M1: ETA | N1: Pre-alert Date | O1: Posi | P1: Column1
A2: Coroplast | C2: TKM Mum nominated | D2: EXW | E2: 43899 | G2: Ham | H2: Nsa | I2: 1115 | J2: 3 pcs | K2: Edison / etd 31.03.2020 | N2: 43925
A3: Coroplast | C3: TKM Mum nominated | D3: EXW | E3: 43899 | G3: Ham | H3: Nsa | I3: 530 | J3: 1 pcs | K3: Edison / etd 31.03.2020 | N3: 43925
A4: Coroplast | C4: TKM Mum nominated | D4: EXW | E4: 43901 | G4: Ham | H4: Nsa | I4: 415 | J4: 1 pcs | K4: Edison / etd 31.03.2020 | N4: 43925
A5: Beka | C5: TSL/2200039874 | D5: FOB | E5: 43902 | G5: Ant | H5: Vtz | I5: 41200 | J5: 2x20' | K5: MSC Maria Saveria / etd 05.04.2020 | N5: 43937
A6: CMI(BSA) | C6: TSL42795/2400002029-DCC03 | D6: FOB | E6: 43886 | G6: Gen | H6: Vtz | I6: 6196 | J6: 1x20'OT(ig) | K6: Ain Snan / etd 05.04.2020 | N6: 43930
A7: CMI(BSA) | C7: TSL/42794/2400002033-DCC03 | D7: FOB | E7: 43886 | G7: Gen | H7: Vtz | I7: 6196 | J7: 1x20'OT(ig) | K7: Ain Snan / etd 05.04.2020 | N7: 43930
A8: Irizar Forge | C8: TSL/44425/2200042530 | D8: EXW | E8: 43899 | G8: Val | H8: CCU | I8: 1756 | J8: 4 pcs | K8: Talos / etd 04.04.2020 | N8: 43937
A9: Irizar Forge | C9: TSL/44165/2200042152 | D9: EXW | E9: 43899 | G9: Val | H9: CCU | I9: 674 | J9: 1 pcs | K9: Talos / etd 04.04.2020 | N9: 43937
A10: Irizar Forge | C10: TSL/44165/2200042152 | D10: EXW | E10: 43899 | G10: Val | H10: CCU | I10: 1566 | J10: 2 pcs | K10: Talos / etd 04.04.2020 | N10: 43937
A11: NKM | C11: CFR | D11: CFR | E11: 43889 | G11: Ham | H11: Nsa | I11: 60000 | J11: 4x40'HC | K11: MSC Ruby / etd 09.04.2020 | N11: 43932
A12: LeLong Vietnam | C12: Agent Nominated Import | D12: CFR | E12: 43931 | G12: Vung Tau | H12: Ham | I12: 40774 | J12: 2x20'DV | K12: ONE Cygnus / ETA 10.04.2020 | N12: 43935
A13: Vesuvius | C13: TSL/2200042890 + 2200043940 | D13: FOB | E13: 43906 | G13: Ant | H13: Vtz | I13: 20560 | J13: 1x40'HC | K13: YM Fountain / etd 11.04.2020 | N13: 43937
... A24: Wheelwash | C24: TSL/45732/2200044263 | D24: EXW | E24: 43943 | G24: Lon | H24: CCU | I24: 700 | J24: 1 pcs | K24: Madrid Bridge / etd 27.04.2020 | N24: 43951
A25: Reimbold | D25: CFR | E25: 43943 | G25: Ham | H25: NSA | I25: 6168 | J25: 6 pcs | K25: Erving / etd 01.05.2020 | N25: 43951
A26: Beka | C26: TSL/2200043787 | D26: FOB | G26: Ant | H26: Hal | I26: 26919 | J26: 1x40'HC, 1x20'DV | K26: Conti Everest / etd 26.04.2020 | N26: 43949
A27: CMI | C27: TSL/42795/2400002029-DCC05 | D27: FOB | E27: 43901 | G27: Gen | H27: Vtz | I27: 112880 | J27: 10x40'HC, 1x20'DV | K27: Thalassa Elpida / etd 28.04.2020 | N27: 43951
A28: CMI | C28: TSL/42793/2400002034-DCC08 | D28: FOB | E28: 43901 | G28: Gen | H28: Vtz | I28: 19170 | J28: 2x40'HC | K28: Thalassa Elpida / etd 28.04.2020 | N28: 43951
A29: Hilger Trading | C29: CFR | D29: CFR | E29: 04.03.20.20 | G29: Ham | H29: Yok | I29: 6000 | J29: 1x40'HC | K29: Bazan / etd 30.04.2020
A30: Z&J | C30: TSL/44136/2200042106 | D30: FOB | E30: 43924 | G30: Ant | H30: CCU | I30: 18141 | J30: 1x40'FR(oog) | K30: Xin Yan Tai / etd 27.04.2020 | N30: 43955
A31: Vesuvius | C31: TSL/2200044155 | D31: FOB | E31: 43909 | G31: Ant | H31: CCU | I31: 60000 | J31: 1x20'DV | K31: Al Safat / etd 09.05.2020 | N31: 43963
A32: Vesuvius | C32: TSL/2200040375 | D32: FOB | E32: 43909 | G32: Ant | H32: CCU | I32: 60000 | J32: 1x40'HC, 1x20'DV | K32: Al Safat / etd 09.05.2020 | N32: 43963
A33: Wheelwash | C33: TSL/45332/2400002164 | D33: FOB | E33: 43924 | G33: Fxt | H33: CCU | I33: 11500 | J33: 1x40'OT(ig) | K33: CS Galaxy / etd 24.04.2020 | N33: 43965
A34: Coroplast | D34: EXW | E34: 43952 | G34: Ham | H34: NSA | I34: 1660 | J34: 5 pcs | K34: Erving / etd 01.05.2020 | N34: 43955
A35: Imerys | C35: TSL/2200041161 | D35: FOB | E35: 43935 | G35: Ant | H35: CCU | I35: 90000 | J35: 4x40'HC | K35: Al Safat / etd 04.05.2020 | N35: 43957
A36: CMI | C36: TSL/42794/2400002033-DCC04 | D36: FOB | E36: 43886 | G36: Ant | H36: Vtz | I36: 3100 | J36: 1x20'DC | K36: Xin Yan Tai / etd 02.05.2020 | N36: 43963
A37: CMI | C37: TSL/42793/2400002034-DCC10 | D37: FOB | E37: 43901 | G37: Ant | H37: Vtz | I37: 11000 | J37: 1x40'FR(oog) | K37: Xin Yan Tai / etd 02.05.2020 | N37: 43963
A38: CMI | C38: TSL/42793/2400002034-DCC07 | D38: FOB | E38: 43946 | G38: Ant | H38: Vtz | I38: 6200 | J38: 1x40'HC | K38: Xin Yan Tai / etd 02.05.2020 | N38: 43963
A39: CMI | C39: TSL/42795/2400002029-DCC06 | D39: FOB | E39: 43901 | G39: Ant | H39: Vtz | I39: 20540 | J39: 1x40'HCOT(oh), 2x40'HC | K39: Xin Yan Tai / etd 02.05.2020 | N39: 43963
A40: CMI | C40: TSL/42793/2400002034-DCC09 | D40: FOB | E40: 43901 | G40: Ant | H40: Vtz | I40: 20540 | J40: 1x40'HCOT(oh), 2x40'HC | K40: Xin Yan Tai / etd 02.05.2020 | N40: 43963
A41: CMI | C41: TSL/42795/2400002029-DCC04 | D41: FOB | E41: 43886 | G41: Ant | H41: Vtz | I41: 3100 | J41: 1x20'DC | K41: Xin Yan Tai / etd 02.05.2020 | N41: 43963
A42: DHM | C42: TSL/45383/2200043405 | D42: EXW | E42: 43945 | G42: Odessa | H42: CCU | I42: 120 | J42: 1 pcs | K42: Navios Summer / etd 13.05.2020 | N42: 43979
A43: DHM | C43: TSL/45188/2200043579 | D43: EXW | E43: 43945 | G43: Odessa | H43: CCU | I43: 220 | J43: 1 pcs | K43: Navios Summer / etd 13.05.2020 | N43: 43979
A44: DHM | C44: TSL/45319/2200043639 | D44: EXW | E44: 43945 | G44: Odessa | H44: CCU | I44: 265 | J44: 1 pcs | K44: Navios Summer / etd 13.05.2020 | N44: 43979
A45: ASA Drilling | C45: TSL/45479/2200043889 | D45: EXW | E45: 43944 | G45: Lon | H45: CCU | I45: 2256 | J45: 2 pcs | K45: ONE Apus / etd 14.05.2020 | N45: 43965
A46: Bronx | C46: TSL/44982/2200043247 | D46: FOB | E46: 43950 | G46: Lon | H46: CCU | I46: 2370 | J46: 3 pcs | K46: UMM Qarn etd 25.05.2020 | N46: 43979
A47: Reimbold | D47: CFR | E47: 43951 | G47: Ham | H47: NSA | I47: 2576.5 | J47: 3 pcs | K47: Ever Genius / etd 21.05.2020 | N47: 43979
A48: Reimbold | D48: CFR | E48: 43959 | G48: Ham | H48: NSA | I48: 6157 | J48: 6 pcs | K48: Ever Genius / etd 21.05.2020 | N48: 43979
A49: Coroplast | D49: EXW | E49: ? | G49: Ham | H49: NSA | I49: 13 | J49: 1 pcs | K49: Ever Genius / etd 21.05.2020 | N49: 43979
A50: BSA | C50: TSL/45044/2200043375 | D50: FOB | E50: 43909 | G50: Gen | H50: CCU | I50: 2572 | J50: 3 pcs | K50: ONE Millau / etd 18.05.2020 | N50: 43987
...

Sheet LCL
A1: Supplier | B1: PO_number | C1: Incoterm | D1: POL | E1: POD | F1: No. of Pieces | G1: Gross Wt. (Kgs) | H1: CBM | I1: Vessel | J1: Release date | K1: Readiness | L1: Days Count (Release Dt. - Readiness Dt.) | M1: Pickup | N1: Arrival at Warehouse | O1: Days Count (Release Dt. - Arrival at WH Dt.) | P1: ETD | Q1: Intended_ETD | R1: Shipped_on_Board | S1: Days Count (Release Dt. - SOB Dt.) | T1: Pre-alert Date | U1: ETA | V1: Z_No | W1: Position_No | X1: HBL | Y1: MBL | Z1: Booking No. | AA1: Remarks | AB1: Additional Remarks | AC1: Pre-alert Remarks | AD1: Pre-Alert saved
A2: GERMANY CCU 1 | AA2: New closing : 11.03.26 // SAC9844 // closing : 11.03.26 // closing : 09.03.26 // closing : 05.03.26 // SAC9828-HMM ROTTERDAM // delayed due to port congestions. | AB2: 91-0002-603-00 // 91-0002-603-01
A3: AHW // Complete Shipment LOT :- 01 // SPA10291 | B3: TSL/57290/2200061379 | C3: FOB | D3: HAM | E3: CCU | F3: 1 | G3: 1220 | H3: 4.59 | I3: ONE RECOMMENDATION V.011E | J3: 46059 | K3: 46062 | L3: =K3-J3 -> 3 | M3: 46066 | N3: 46071 | O3: =IF(ISBLANK(N3)=TRUE,TODAY()-J3,N3-J3) -> 12 | P3: 46103 | Q3: 46099 | R3: 46103 | S3: =IF(ISBLANK(R3)=TRUE,TODAY()-J3,R3-J3) -> 44 | U3: 46166 | V3: Z26001017217 | W3: 22-0006-604-00 | X3: 22-0006-604-00 | Y3: CCU209247 | Z3: CCU209210 | AA3: Shipped - Pre-alert to be sent // Booked on 10.02.26 // Supplier's response & SPA rcvd on 06.02.26 // MRN rcvd on 09.02.26 // The trucking company has advised that the shipment was not loaded due to a transmission error, as the partner did not receive the booking. Loading is now scheduled for 13.02.26, with delivery on 17.02.26 // Rolled to next vessel on 17.02.26 as not reached WH till 16.02.26 // Carrier informed on 19.02.26 that Vessel changed to ONE Innovation due to early arrival of HMM Copenhagen and earlier VGM deadline. New schedule: Closing 24.02, ETD 02.03 // On 20.02.26, the carrier informed that the vessel ONE Innovation is delayed due to port congestion // Rolled to next vessel on 25.02.26 as ONE INNOVATION closed on 25.02.26 // As on 06.03.26 The vessel is delayed due to port congestion, and delays may increase due to the current situation in the Middle East // Carrier informed on 10.03.2026 that cargo has been booked on an earlier vessel ONE RECOMMENDATION // On 17.03.26, the carrier informed that the vessel ONE Recommendation is delayed due to adverse weather conditions on the import-bound leg. The revised ETA at Hamburg is now 22.03.26. | AB3: Non-stackable // We need to charge the supplier for the repacking charges-Euro 1000
A4: Paul Wurth S.A. | B4: TSL/57023/2200060988 | C4: FOB | D4: HAM | E4: CCU | F4: 1 | G4: 2040 | H4: 4.762 | I4: ONE RECOMMENDATION V.011E | J4: 46077 | K4: 46083 | L4: =K4-J4 -> 6 | M4: - | N4: 46086 | O4: =IF(ISBLANK(N4)=TRUE,TODAY()-J4,N4-J4) -> 9 | P4: 46103 | Q4: 46099 | R4: 46103 | S4: =IF(ISBLANK(R4)=TRUE,TODAY()-J4,R4-J4) -> 26 | U4: 46166 | V4: Z26001444561 | W4: 22-0007-604-00 | X4: 22-0007-604-00 | Y4: CCU209247 | Z4: CCU209247 | AA4: Shipped - Pre-alert to be sent // Booked on 26.02.26 // Supplier response rcvd on 26.02.26 // As on 06.03.26 The vessel is delayed due to port congestion, and delays may increase due to the current situation in the Middle East // Carrier informed on 10.03.2026 that cargo has been booked on an earlier vessel // Carrier informed on 10.03.2026 that cargo has been booked on an earlier vessel ONE RECOMMENDATION // On 17.03.26, the carrier informed that the vessel ONE Recommendation is delayed due to adverse weather conditions on the import-bound leg. The revised ETA at Hamburg is now 22.03.26. | AB4: Non-stackable
A5: GERMANY CCU 2 | AA5: New closing : 18.03.26 // closing : 17.03.26 // closing : 12.03.26 // closing : 11.03.26 // closing : 09.03.26 // closing : 05.03.26 // SAC9828-HMM ROTTERDAM // delayed due to port congestions. | AB5: 91-0003-603-00 // 91-0003-603-01
A6: SMS CONCAST AG // PARTIAL SHIPMENT LOT- 3 | B6: TSL/55639/2200058575 | C6: FOB | D6: HAM | E6: CCU | F6: 2 | G6: 1039 | H6: 1.44 | I6: HMM ROTTERDAM V.018E | J6: 46064 | K6: 46094 | L6: =K6-J6 -> 30 | M6: - | N6: 46098 | O6: =IF(ISBLANK(N6)=TRUE,TODAY()-J6,N6-J6) -> 34 | P6: 46106 | Q6: 46097 | S6: =IF(ISBLANK(R6)=TRUE,TODAY()-J6,R6-J6) -> 41 | U6: 46160 | V6: Z26001850220 | W6: 22-0008-604-00 | X6: 22-0008-604-00 | Y6: CCU209234 | Z6: CCU209234 | AA6: Sailing awaited // Booking updated on 20.02.26 // Booked on 18.02.26 // Supplier response rcvd on 13.02.26 // On 19.02.26, the supplier requested to shift the vessel to a later closing date, preferably no earlier than the end of next week, as the shipment is currently in Switzerland and the T1 and EUR.1 certificates are still to be issued // Carrier informed on 19.02.26 that Vessel changed to ONE Innovation due to early arrival of HMM Copenhagen and earlier VGM deadline - New schedule: Closing 24.02, ETD 02.03 // On 20.02.26, the carrier informed that the vessel ONE Innovation is delayed due to port congestion // Supplier informed on 20.02.26 that they will issue the T1 at beginning of next week // On 20.02.26 carrier informed that vessel delayed due to port congestions // As on 06.03.26 The vessel is delayed due to port congestion, and delays may increase due to the current situation in the Middle East // Supplier confirmed on 10.03.26 that they will provide the MRN, and no T1 document will be issued for this shipment. MRN rcvd on 13.03.26 // On 16.03.26 carrier informed that vessel HMM Rotterdam is delayed due to port congestions. | AB6: Stackable
A7: PRIMETALS TECHNOLOGIES // COMPLETE SHIPMENT LOT- 1 | B7: TSL/56966/2200060906 | C7: FOB | D7: HAM | E7: CCU | F7: 1 | G7: 420 | H7: 1.651 | I7: HMM ROTTERDAM V.018E | J7: 46080 | K7: 46083 | L7: =K7-J7 -> 3 | M7: 46090 | N7: 46093 | O7: =IF(ISBLANK(N7)=TRUE,TODAY()-J7,N7-J7) -> 13 | P7: 46106 | Q7: 46097 | S7: =IF(ISBLANK(R7)=TRUE,TODAY()-J7,R7-J7) -> 25 | U7: 46160 | V7: Z26001494351 | W7: 22-0009-604-00 | X7: 22-0009-604-00 | Z7: CCU209257 | AA7: Sailing awaited // Booked on 03.03.26 // Supplier response & MRN rcvd on 02.03.26 // As on 06.03.26 The vessel is delayed due to port congestion, and delays may increase due to the current situation in the Middle East // On 12.03.26, it was mentioned in the CWR that 1 x packaging was damaged - Carrier taped the package on 17.03.26 // On 16.03.26 carrier informed that vessel HMM Rotterdam is delayed due to port congestions. | AB7: Stackable // Repairing charges would be EUR 180 billed to supplier
A8: ALPINE METAL // COMPLETE SHIPMENT LOT- 1 | B8: TSL/57653/2200061997 | C8: FOB | D8: HAM | E8: CCU | F8: 1 | G8: 1520 | H8: 1.424 | I8: HMM ROTTERDAM V.018E | J8: 46084 | K8: 46084 | L8: =K8-J8 -> 0 | M8: - | N8: 46092 | O8: =IF(ISBLANK(N8)=TRUE,TODAY()-J8,N8-J8) -> 8 | P8: 46106 | Q8: 46101 | S8: =IF(ISBLANK(R8)=TRUE,TODAY()-J8,R8-J8) -> 21 | U8: 46160 | V8: Z26001710968 | W8: 22-0010-604-00 | X8: 22-0010-604-00 | Z8: CCU209261 | AA8: Sailing awaited // Booked on 05.03.26 // Supplier response & MRN rcvd on 03.03.26 // As on 06.03.26 The vessel is delayed due to port congestion, and delays may increase due to the current situation in the Middle East // On 16.03.26 carrier informed that vessel HMM Rotterdam is delayed due to port congestions. | AB8: Stackable
A9: BUCK // Complete Shipment LOT :- 01 | B9: TSL/56554/2200060284 | C9: EXW | D9: HAM | E9: CCU | F9: 1 | G9: 959 | H9: 0.343 | I9: HMM ROTTERDAM V.018E | J9: 46084 | K9: 46087 | L9: =K9-J9 -> 3 | M9: 46087 | N9: 46093 | O9: =IF(ISBLANK(N9)=TRUE,TODAY()-J9,N9-J9) -> 9 | P9: 46106 | Q9: 46101 | S9: =IF(ISBLANK(R9)=TRUE,TODAY()-J9,R9-J9) -> 21 | U9: 46160 | V9: S26100029103 | W9: 22-0011-604-00 | X9: 22-0011-604-00 | Z9: CCU209262 | AA9: Sailing awaited // Booked on 05.03.26 // Supplier response rcvd on 03.03.26 // T1 rcvd on 06.03.26 // As on 06.03.26 The vessel is delayed due to port congestion, and delays may increase due to the current situation in the Middle East // On 12.03.26, it was mentioned 1 x SKIDS ARE DAMAGED in the CWR - Carrier taped the package on 18.03.26 // On 16.03.26 carrier informed that vessel HMM Rotterdam is delayed due to port congestions. | AB9: Non-stackable
A10: GERMANY CCU 3 | AA10: New closing : 24.03.26 // Closing : 23.03.26 // SAC9829 | AB10: 91-0001-604-00
A11: TMT // COMPLETE SHIPMENT LOT- 1 | B11: TSL/57339/2200061522 | C11: EXW | D11: HAM | E11: CCU | F11: 1 | G11: 850 | H11: 0.852 | I11: HMM ST PETERSBURG V.017E | J11: 46087 | K11: 46087 | L11: =K11-J11 -> 0 | M11: 46092 | N11: 46094 | O11: =IF(ISBLANK(N11)=TRUE,TODAY()-J11,N11-J11) -> 7 | P11: 46112 | Q11: 46111 | S11: =IF(ISBLANK(R11)=TRUE,TODAY()-J11,R11-J11) -> 18 | U11: 46162 | V11: Z26001711792 | W11: 22-0012-604-00 | X11: 22-0012-604-00 | Z11: CCU209265 | AA11: Booked on 06.03.26 // MRN available // Supplier response rcvd on 06.03.26 // Trucker informed on 11.03.26 that their partner unfortunately could not pick up the shipment yesterday. Therefore, the pickup has been rescheduled for 11.03.26 // On 16.03.26 carrier informed that vessel HMM Rotterdam is delayed due to port congestions. // The carrier on 18.03.26 informed that the shipment has been rolled over due to space constraints // The carrier has informed on 20.03.26 that the vessel HMM St. Petersburg is delayed due to port congestion. | AB11: Stackable
A12: CHINA CCU
A13: CHANGZHI // ST00002290 | B13: TSL/2200061760 | C13: FOB | D13: TJN | E13: CCU | F13: 1 | G13: 705 | H13: 0.705 | I13: TBA | J13: 46080 | K13: 46080 | L13: =K13-J13 -> 0 | M13: - | N13: 46094 | O13: =IF(ISBLANK(N13)=TRUE,TODAY()-J13,N13-J13) -> 14 | P13: 46106 | Q13: 46099 | S13: =IF(ISBLANK(R13)=TRUE,TODAY()-J13,R13-J13) -> 25 | U13: 46123 | V13: - | X13: SGE25260279 | AA13: Sailing awaited // Booked // Supplier response rcvd on 06.03.26 // TKM China team informed on 16.03.26 that since the shipper’s packing needs to be redone, the shipment is now booked for ETD 25.03.26
A14: BEIJING WIS WIZ // ST00002312 | B14: TSL/2200061732 | C14: FOB | D14: XIN | E14: CCU | F14: 2 | G14: 1030 | H14: 4.86 | I14: TBA | J14: 46085 | K14: 46098 | L14: =K14-J14 -> 13 | M14: - | O14: =IF(ISBLANK(N14)=TRUE,TODAY()-J14,N14-J14) -> 20 | S14: =IF(ISBLANK(R14)=TRUE,TODAY()-J14,R14-J14) -> 20 | V14: - | X14: SGE25260290 | Y14: GTJCOL26030193 | AA14: Booking confirmation awaited
A15: Metallon Holdings Limited // Exceeds contractual lot limit. | B15: TSL/57444/2200061614 | C15: EXW | D15: TJN | E15: CCU | F15: 1 | G15: 1416 | H15: =290*180*170/1000000 -> 8.874 | I15: TBA | J15: 46094 | K15: 46099 | L15: =K15-J15 -> 5 | M15: - | N15: 46102 | O15: =IF(ISBLANK(N15)=TRUE,TODAY()-J15,N15-J15) -> 8 | P15: 46113 | Q15: 46114 | S15: =IF(ISBLANK(R15)=TRUE,TODAY()-J15,R15-J15) -> 11 | U15: 46144 | V15: - | W15: 32-0001-604-00 | X15: SGE25260292 | Y15: GTJCOL26030241 | AA15: Booked on 18.03.26 // Cargo transit to TJN is approximately 5 days, targeting ETD 02 April // Revised docs with correct incoterm rcvd on 17.03.26 | AB15: overlength freight
A16: CHINA NSA
A17: CHANGZHOU ECCO ROLLER CO.,LTD // ST00002344 | B17: TSL/2200059445 | C17: TBA | D17: SHG | E17: NSA | F17: 2 | G17: 8400 | H17: 4.731 | J17: 46094 | L17: =K17-J17 -> -46094 | O17: =IF(ISBLANK(N17)=TRUE,TODAY()-J17,N17-J17) -> 11 | S17: =IF(ISBLANK(R17)=TRUE,TODAY()-J17,R17-J17) -> 11 | V17: - | AA17: Confirmation from Tata Steel on the quote is still awaited. | AB17: NS //
A18: ITALY CCU
A19: TECNO // Complete Shipment LOT :- 01 | B19: TSL/57374/2200061473 | C19: EXW | D19: GEN | E19: CCU | F19: 1 | G19: 1660 | H19: 1.755 | I19: ONE FRIENDSHIP / 011E | J19: 46084 | K19: 46084 | L19: =K19-J19 -> 0 | M19: 46090 | N19: 46091 | O19: =IF(ISBLANK(N19)=TRUE,TODAY()-J19,N19-J19) -> 7 | P19: 46102 | Q19: 46099 | S19: =IF(ISBLANK(R19)=TRUE,TODAY()-J19,R19-J19) -> 21 | U19: 46150 | V19: - | W19: 22-0014-604-00 | X19: 22-0015-603-00 | Y19: MILCCU6232051V | Z19: MILCCU6232051V | AA19: Sailing confirmation awaited // In tracking showing ETD 23.03.26 // Booked on 04.03.26 // Closing :12.03.26 // MRN by us // This is the first available vessel // Delay - due to strong congestion at port and delay to previous shipment | AB19: NS // WD2603107080 // Rev MBL correct // MRN rec on 12.03.26
A20: PICCARDI S.r.L // Complete Shipment LOT :- 01 | B20: TSL/57462/2200061588 | C20: FOB | D20: GEN | E20: CCU | F20: 1 | G20: 358.3 | H20: 0.482 | I20: ONE FRIENDSHIP / 011E | J20: 46084 | K20: 46084 | L20: =K20-J20 -> 0 | M20: 46090 | N20: 46090 | O20: =IF(ISBLANK(N20)=TRUE,TODAY()-J20,N20-J20) -> 6 | P20: 46102 | Q20: 46099 | S20: =IF(ISBLANK(R20)=TRUE,TODAY()-J20,R20-J20) -> 21 | U20: 46150 | V20: - | W20: 23-0001-604-00 | X20: 23-0003-603-00 | Y20: MILCCU6232118V | Z20: MILCCU6232118V | AA20: Sailing confirmation awaited // In tracking showing ETD 23.03.26 // Booked on 04.03.26 // Closing :12.03.26 // MRN rcvd on 11.03.26 // This is the first available vessel// Delay - due to strong congestion at port and delay to previous shipment | AB20: NS // WD2603107274 // Draft MBL correct // MRN REC ON 11.03
A21: ITALY NSA
A22: UK
A23: COREWIRE LIMITED | B23: TSL/57671/4416366332 | C23: EXW | D23: LON | E23: CCU | F23: 8 | G23: 6340 | H23: 8.358 | I23: MAERSK MC-KINNEY MOLLER / 611E | J23: 46086 | K23: 46086 | L23: =K23-J23 -> 0 | M23: 46090 | N23: 46091 | O23: =IF(ISBLANK(N23)=TRUE,TODAY()-J23,N23-J23) -> 5 | P23: 46101 | Q23: 46101 | S23: =IF(ISBLANK(R23)=TRUE,TODAY()-J23,R23-J23) -> 19 | U23: 46133 | V23: - | W23: 22-0004-604-00 | X23: UINCCU021867 | Y23: UINCCU021895 | Z23: SUSE26021867 | AA23: Sailing awaited // Booked on 06.03.26 // Closing : 16.03.26 // This is the first available vessel. | AB23: Non Stackable // HBL correct // Draft MBL rcvd on 16.03.25
A24: CANADA
A25: METAL 7 // COMPLETE SHIPMENT LOT- 1 | B25: TSL/57472/2200061692 | C25: EXW | D25: HAL | E25: CCU | F25: 4 | G25: 3334 | H25: 3.92 | I25: HMM SAPPHIRE / 010W | J25: 46091 | K25: 46091 | L25: =K25-J25 -> 0 | M25: 46094 | N25: 46097 | O25: =IF(ISBLANK(N25)=TRUE,TODAY()-J25,N25-J25) -> 6 | P25: 46115 | Q25: 46115 | S25: =IF(ISBLANK(R25)=TRUE,TODAY()-J25,R25-J25) -> 14 | U25: 46145 | V25: - | W25: 22-0005-604-00 | Z25: MTRCCU6103984V | AA25: Sailing awaited // Booked on 11.03.26 // closing : 27.03.26 // Supplier response rcvd 10.03.26 that they need flatbed truck // This is the first available vessel. | AB25: Stackable // Draft HBL/MBL awaited
A26: USA
A27: Mi-Jack Products Inc. | B27: TSL/57595/2200061922 | C27: EXW | D27: LAX | E27: CCU | F27: 2 | G27: 576.0623 | H27: 1.117 | I27: ONE HARBOUR V.103W | J27: 46093 | K27: 46093 | L27: =K27-J27 -> 0 | M27: 46098 | N27: 46099 | O27: =IF(ISBLANK(N27)=TRUE,TODAY()-J27,N27-J27) -> 6 | P27: 46118 | Q27: 46118 | S27: =IF(ISBLANK(R27)=TRUE,TODAY()-J27,R27-J27) -> 12 | U27: 46153 | V27: - | W27: 22-0013-604-00 | X27: ORDSE0247080 | Y27: CHI/CTA/V03422 | Z27: CHI/CTA/V03422 | AA27: Sailing awaited // Booked 17.03.26 // closing : 18.03.26 // Supplier response rcvd on 12.03.26 // This is the first available vessel. | AB27: Non-stackable // Draft HBL/MBL 20.03.26
A28: NON-TATA
A29: Intensiv Filter | B29: SOC-04579 | C29: CIF | D29: HAM | E29: JED | F29: 3 | G29: 695 | H29: 5.357 | I29: SAVANNAH EXPRESS | J29: 46044 | L29: =K29-J29 -> -46044 | O29: =IF(ISBLANK(N29)=TRUE,TODAY()-J29,N29-J29) -> 61 | P29: 46063 | Q29: 46110 | R29: 46071 | S29: =IF(ISBLANK(R29)=TRUE,TODAY()-J29,R29-J29) -> 27 | T29: 46072 | V29: Z26000667113 | W29: 28-0008-602-00 | X29: 28-0008-602-00 | Z29: SEME26020002704 | AA29: Pick-up details awaited // booking confirmation received
A30: Impact - Maxxove | B30: 2025-40038 | C30: CFR | D30: HAM | E30: JEA | F30: 3 | G30: 2247 | H30: 3.074 | I30: SAVANNAH EXPRESS | J30: 46050 | L30: =K30-J30 -> -46050 | M30: 46052 | N30: 46055 | O30: =IF(ISBLANK(N30)=TRUE,TODAY()-J30,N30-J30) -> 5 | P30: 46066 | Q30: 46099 | R30: 46071 | S30: =IF(ISBLANK(R30)=TRUE,TODAY()-J30,R30-J30) -> 21 | T30: 46072 | V30: Z26000673872 | W30: 28-0009-602-00 | X30: 28-0009-602-00 | Z30: SEME26020002708 | AA30: goods has been delivered to the warehouse /
A31: Intensiv Filter | B31: SOC-04348 // MM-010-10-25 | C31: CIF | D31: HAM | E31: EDK | F31: 4 | G31: 1015 | H31: 4.138 | I31: EXPRESS SPAIN | J31: 46051 | K31: 46051 | L31: =K31-J31 -> 0 | M31: 46051 | N31: 46070 | O31: =IF(ISBLANK(N31)=TRUE,TODAY()-J31,N31-J31) -> 19 | P31: 28.03.2026 | S31: =IF(ISBLANK(R31)=TRUE,TODAY()-J31,R31-J31) -> 54 | U31: 15.04.2026 | V31: Z26001435390 | W31: 25-0011-603-00 | X31: 25-0011-603-00 | Z31: EDK217768 / 1088027 | AA31: ACID number received on 16.02.2026 // physical inspection needed / customs have been contacted / waiting for the release
A32: John Zink - Balmer Lawrie | B32: 4070059507 | C32: FOB | D32: ANT | E32: NSA | F32: 1 | G32: 345 | H32: 2.19 | I32: MV One Reliability | J32: 46064 | K32: 46070 | L32: =K32-J32 -> 6 | M32: 46072 | O32: =IF(ISBLANK(N32)=TRUE,TODAY()-J32,N32-J32) -> 41 | P32: 09.03.2026 | Q32: 02.03.2026 | R32: 46090 | S32: =IF(ISBLANK(R32)=TRUE,TODAY()-J32,R32-J32) -> 26 | T32: 46101 | U32: 08.04.2026 | V32: - | W32: 25-0013-603-00 | X32: 25-0013-603-00 | Y32: B2601714 | Z32: B2601714 | AA32: received MBL
A33: WEG Gear Systems GmbH - Balmer Lawrie | B33: RITM11181450 // 4130002885 | C33: EXW | D33: HAM | E33: NSA | F33: 2 | G33: 2024 | H33: 6.134 | I33: ONE RECOMMENDATION | J33: 02.03.2026 | K33: 02.03.2026 | L33: =K33-J33 -> #VALUE! | M33: 05.03.2026 | O33: =IF(ISBLANK(N33)=TRUE,TODAY()-J33,N33-J33) -> #VALUE! | P33: 22.03.2026 | V33: Z26001669900 | W33: 25-0027-603-00 | X33: 25-0027-603-00 | Z33: 50-0326-5093-13 | AA33: SSS , HBL confirmed, MBL received
A34: J A Becker& Söhne - Balmer Lawrie | B34: 4130002910 | C34: EXW | D34: HAM | E34: NSA | F34: 1 | G34: 775 | H34: 4.139 | I34: ONE RECOMMENDATION | J34: 23.02.2026 | K34: 46080 | L34: =K34-J34 -> #VALUE! | M34: 02.03.2026 | N34: 10.03.2026 | O34: =IF(ISBLANK(N34)=TRUE,TODAY()-J34,N34-J34) -> #VALUE! | P34: 22.03.2026 | V34: Z26001609058 | W34: 25-0023-603-00 | X34: 25-0023-603-00 | Z34: 50-0326-5093-09 | AA34: seven seas, MBL received, HBL confirmed
A35: Impact - Maxxove | B35: 2025-40068 IISCO | C35: CFR | D35: HAM | E35: NSA | F35: 3 | G35: 2999 | H35: 3.716 | I35: ONE RECOMMENDATION | J35: 03.03.2026 | K35: 03.03.2026 | L35: =K35-J35 -> #VALUE! | M35: 04.03.2026 | O35: =IF(ISBLANK(N35)=TRUE,TODAY()-J35,N35-J35) -> #VALUE! | P35: 22.03.2026 | Q35: 46099 | U35: 10.05.2026 | V35: Z26001598076 | W35: 25-0024-603-00 | X35: 25-0024-603-00 | Z35: SEIN26030010212 | AA35: WOAC, original BL // awaiting final BL / HBL confirmed + certificate confirmed
A36: MALMEDIE - Balmer Lawrie | B36: 4130002913, uns. Ref. AB25624 | C36: FOB | D36: HAM | E36: NSA | F36: 1 | G36: 1585 | H36: 1.378 | I36: BF HAMBURG | J36: 09.03.2026 | K36: 05.03.2026 | L36: =K36-J36 -> #VALUE! | P36: 26.03.2026 | Q36: 46104 | V36: Z26001847975 | W36: 25-0001-604-00 | X36: 25-0001-604-00 | Z36: 50-0326-5099-08 | AA36: seven seas // rec. MBL draft is okay // HBL draft confirmation awaited
A37: John Zink - Balmer Lawrie | B37: GAIL/PA25/30812/5100004373 | C37: FOB | D37: ANT | E37: NSA | F37: 1 | G37: 259 | H37: 0.61 | I37: BF HAMBURG | J37: 04.03.2026 | K37: 04.03.2026 | L37: =K37-J37 -> #VALUE! | M37: 46097 | N37: 46099 | O37: =N37-M37 -> 2 | P37: 25.03.2026 | U37: 28.04.2026 | V37: - | W37: 25-0004-604-00 | X37: 25-0004-604-00 | Z37: B2602743 | AA37: NS, Cleve // HBL and MBL draft confirmation awaited
A38: Impact - Maxxove | B38: 2026-40002 | C38: CIF | D38: HAM | E38: MAA | F38: 4 | G38: 3626 | H38: 4643 | I38: MAERSK SAVANNAH | J38: 46087 | K38: 46090 | L38: =K38-J38 -> 3 | M38: 46093 | P38: 46111 | U38: 46144 | Z38: SEIN26030011709 | AA38: WOAC
A39: Impact - Maxxove | B39: 2025-40032 | Fourth partial delivery | C39: CIF | D39: HAM | E39: MAA | F39: 2 | G39: 2428 | H39: 3471 | I39: MAERSK SEOUL | J39: 46097 | K39: 46097 | L39: =K39-J39 -> 0 | M39: 46104 | P39: 46117 | U39: 46151 | Z39: SEIN26040015207 | AA39: WOAC
A40: PROFINE | B40: Tour 1010699377 | C40: CIF | D40: HAM | E40: NAS | F40: 3 | G40: 2652 | J40: 46069 | K40: 46097 | L40: =K40-J40 -> 28 | O40: =IF(ISBLANK(N40)=TRUE,TODAY()-J40,N40-J40) -> 36 | U40: 30.04.2026 | AA40: Readiness of the goods from KW12 // DG GOODS / SACO: offer Nr. 290047 // CIPL will be provided the day before pick-up
...

Sheet LCL Completed
A1: Supplier | B1: PO number | C1: Incoterm | D1: POL | E1: POD | F1: No. of Pieces | G1: Gross Wt. (Kgs) | H1: CBM | I1: Vessel | J1: Release date | K1: Readiness | L1: Days Count (Release Dt. - Readiness Dt.) | M1: Pickup | N1: Arrival at Warehouse | O1: Days Count (Release Dt. - Arrival at WH Dt.) | P1: ETD | Q1: Intended ETD | R1: Shipped on Board | S1: Days Count (Release Dt. - SOB Dt.) | T1: Pre-alert Date | U1: Z NO. // ETA | V1: Z No. | W1: Position No. | X1: HBL | Y1: MBL | Z1: Booking No. | AA1: Remarks | AB1: Additional Remarks | AC1: Pre-alert Remarks | AD1: Pre-Alert saved | AE1: Final commercial docs. Status | AF1: Error in release mail
A2: Maina | B2: TSL/48838/2299900795 | C2: FOB | D2: GEN | E2: CCU | F2: 2 pcs | G2: 5480 | H2: 6.66 | I2: Al Riffa | J2: 44630 | K2: 44634 | M2: 44635 | N2: 44637 | O2: =IF(ISBLANK(N2)=TRUE,TODAY()-J2,N2-J2) -> 7 | P2: 44664 | Q2: 44644 | R2: 44664 | S2: =IF(ISBLANK(R2)=TRUE,TODAY()-J2,R2-J2) -> 34 | T2: 44670 | X2: 23-0001-204 | AA2: rebooked by Carrier ex Alula Express / etd 24.03.2022
A3: Tecno Vibrazioni | B3: TSL/47735/22000047068 | C3: EXW | D3: GEN | E3: CCU | F3: 1 pcs | G3: 350 | H3: 1.33 | I3: Al Riffa | J3: 44631 | K3: 44635 | M3: 44636 | N3: 44638 | O3: =IF(ISBLANK(N3)=TRUE,TODAY()-J3,N3-J3) -> 7 | P3: 44664 | Q3: 44644 | R3: 44664 | S3: =IF(ISBLANK(R3)=TRUE,TODAY()-J3,R3-J3) -> 33 | T3: 44670 | X3: 22-0005-204 | AA3: stopped by TLL, released on 15.03.2022 // rebooked by Carrier ex Alula Express / etd 24.03.2022
A4: Thermocast | B4: TSL/48915/2200048530 | C4: FOB | D4: GEN | E4: CCU | F4: 1 pcs | G4: 1620 | H4: 2.09 | I4: Al Riffa | J4: 44634 | K4: 44635 | M4: 44636 | N4: 44638 | O4: =IF(ISBLANK(N4)=TRUE,TODAY()-J4,N4-J4) -> 4 | P4: 44664 | Q4: 44644 | R4: 44664 | S4: =IF(ISBLANK(R4)=TRUE,TODAY()-J4,R4-J4) -> 30 | T4: 44670 | X4: 22-0007-204 | AA4: rebooked by Carrier ex Alula Express / etd 24.03.2022
A5: Tenova | B5: TSL/48487/2200048172 | C5: FOB | D5: GEN | E5: CCU | F5: 1 pcs | G5: 675 | H5: 3.381 | I5: Al Riffa | J5: 44634 | K5: 44638 | N5: 44642 | O5: =IF(ISBLANK(N5)=TRUE,TODAY()-J5,N5-J5) -> 8 | P5: 44664 | Q5: 44644 | R5: 44664 | S5: =IF(ISBLANK(R5)=TRUE,TODAY()-J5,R5-J5) -> 30 | T5: 44670 | X5: 22-0006-204 | AA5: rebooked by Carrier ex Alula Express / etd 24.03.2022
A6: Thermocast | B6: TSL/48969/2200048665 | C6: FOB | D6: GEN | E6: CCU | F6: 2 pcs | G6: 3480 | H6: 4.95 | I6: Al Riffa | J6: 44644 | K6: 44644 | M6: 44648 | N6: 44650 | O6: =IF(ISBLANK(N6)=TRUE,TODAY()-J6,N6-J6) -> 6 | P6: 44664 | Q6: 44664 | R6: 44664 | S6: =IF(ISBLANK(R6)=TRUE,TODAY()-J6,R6-J6) -> 20 | T6: 44670 | X6: 22-0009-204 | AA6: vessel delayed Al Riffa / etd 31.03.2022
A7: Refra Technik | B7: 4300026803 | C7: CFR | D7: HAM | E7: MNL | F7: 1 pcs | G7: 223kgs | H7: 0.995 | I7: CMA CGM Zheng He | J7: 44638 | K7: 44638 | M7: 44648 | N7: 44649 | O7: =IF(ISBLANK(N7)=TRUE,TODAY()-J7,N7-J7) -> 11 | Q7: 44665 | R7: 44665 | S7: =IF(ISBLANK(R7)=TRUE,TODAY()-J7,R7-J7) -> 27 | T7: 44665 | X7: 25-0006-204 | AA7: Rebooked by Carrier from Ever Gifted / etd 07.04.2022
A8: Reel | C8: CFR | D8: HAM | E8: SHA | F8: 1 pcs | G8: 360 | H8: 0.672 | I8: CP Universe | J8: 44645 | K8: 44648 | M8: 44651 | N8: 44656 | O8: =IF(ISBLANK(N8)=TRUE,TODAY()-J8,N8-J8) -> 11 | Q8: 44664 | R8: 44669 | S8: =IF(ISBLANK(R8)=TRUE,TODAY()-J8,R8-J8) -> 24 | T8: 44673 | X8: 25-0008-204
A9: BSA | B9: TSL/48330/2200047730 | C9: FOB | D9: GEN | E9: CCU | F9: 2 pcs | G9: 2886 | H9: 3.36 | I9: Milano Bridge | J9: 44616 | K9: 44650 | M9: 44650 | N9: 44651 | O9: =IF(ISBLANK(N9)=TRUE,TODAY()-J9,N9-J9) -> 35 | P9: 44669 | Q9: 44666 | R9: 44669 | S9: =IF(ISBLANK(R9)=TRUE,TODAY()-J9,R9-J9) -> 53 | T9: 44672 | X9: 22-0004-204 | AA9: vessel delayed Milano Bridge / etd 15.04.2022
A10: Tecno Vibrazioni | B10: TSL/49093/2200048866 | C10: EXW | D10: GEN | E10: CCU | F10: 1 pcs | G10: 260 | H10: 0.576 | I10: Milano Bridge | J10: 44650 | K10: 44652 | M10: 44655 | N10: 44657 | O10: =IF(ISBLANK(N10)=TRUE,TODAY()-J10,N10-J10) -> 7 | P10: 44669 | Q10: 44666 | R10: 44669 | S10: =IF(ISBLANK(R10)=TRUE,TODAY()-J10,R10-J10) -> 19 | T10: 44672 | X10: 22-0026-204 | AA10: vessel delayed Milano Bridge / etd 15.04.2022
A11: Impact / Jiangsu | C11: CFR | D11: HAM | E11: NSA | F11: 3 pcs | G11: 2003 | H11: 2.874 | I11: Northern Justice | J11: 44650 | K11: 44651 | M11: 44651 | N11: 44656 | O11: =IF(ISBLANK(N11)=TRUE,TODAY()-J11,N11-J11) -> 6 | Q11: 44662 | R11: 44674 | S11: =IF(ISBLANK(R11)=TRUE,TODAY()-J11,R11-J11) -> 24 | T11: 44676 | X11: 25-0007-204
A12: PWL | B12: TSL/49050/2200048660 | C12: FOB | D12: HAM | E12: CCU | F12: 1 pcs | G12: 255 | H12: 1.764 | I12: Northern Justice | J12: 44643 | K12: 44610 | N12: 44648 | O12: =IF(ISBLANK(N12)=TRUE,TODAY()-J12,N12-J12) -> 5 | P12: 44674 | Q12: 44622 | R12: 44674 | S12: =IF(ISBLANK(R12)=TRUE,TODAY()-J12,R12-J12) -> 31 | T12: 44679 | X12: 22-0031-204 | AA12: rebooked by Carrier ex MSC Aliya / ETD 02.03.2022
A13: Binder | B13: TSL/48696/2200047482 | C13: EXW | D13: HAM | E13: CCU | F13: 6 pcs | G13: 9345 | H13: 35.774 | I13: Northern Justice | J13: 44608 | K13: 44609 | M13: 44613 | N13: 44620 | O13: =IF(ISBLANK(N13)=TRUE,TODAY()-J13,N13-J13) -> 12 | P13: 44674 | Q13: 44622 | R13: 44674 | S13: =IF(ISBLANK(R13)=TRUE,TODAY()-J13,R13-J13) -> 66 | T13: 44679 | X13: 22-0018-203 | AA13: rebooked by Carrier ex MSC Aliya / ETD 02.03.2022
A14: Malmedie | B14: TSL/49150/3700847821 | C14: FOB | D14: HAM | E14: CCU | F14: 1 pcs | G14: 1550 | H14: 1.14 | I14: Northern Justice | J14: 44614 | K14: 44615 | N14: 44617 | O14: =IF(ISBLANK(N14)=TRUE,TODAY()-J14,N14-J14) -> 3 | P14: 44674 | Q14: 44622 | R14: 44674 | S14: =IF(ISBLANK(R14)=TRUE,TODAY()-J14,R14-J14) -> 60 | T14: 44679 | X14: 22-0020-203 | AA14: rebooked by Carrier ex MSC Aliya / ETD 02.03.2022
A15: Malmedie | B15: TSL/49151/3700845190 | C15: FOB | D15: HAM | E15: CCU | F15: 1 pcs | G15: 518 | H15: 0.573 | I15: Northern Justice | J15: 44613 | K15: 44615 | N15: 44617 | O15: =IF(ISBLANK(N15)=TRUE,TODAY()-J15,N15-J15) -> 4 | P15: 44674 | Q15: 44622 | R15: 44674 | S15: =IF(ISBLANK(R15)=TRUE,TODAY()-J15,R15-J15) -> 61 | T15: 44679 | X15: 22-0023-203 | AA15: rebooked by Carrier ex MSC Aliya / ETD 02.03.2022
A16: Eich | B16: TSL/48301/2200047899 | C16: EXW | D16: HAM | E16: CCU | F16: 1 pcs | G16: 784 | H16: 0.843 | I16: Northern Justice | J16: 44637 | K16: 44642 | M16: 44644 | N16: 44649 | O16: =IF(ISBLANK(N16)=TRUE,TODAY()-J16,N16-J16) -> 12 | P16: 44674 | Q16: 44665 | R16: 44674 | S16: =IF(ISBLANK(R16)=TRUE,TODAY()-J16,R16-J16) -> 37 | T16: 44679 | X16: 22-0028-204 | AA16: rebooked by Carrier ex Seamax Fairfield / etd 14.04.2022
A17: Eich | B17: TSL/48335/3700839504 | C17: EXW | D17: HAM | E17: CCU | F17: 2 pcs | G17: 1536 | H17: 1.226 | I17: Northern Justice | J17: 44638 | K17: 44642 | M17: 44644 | N17: 44649 | O17: =IF(ISBLANK(N17)=TRUE,TODAY()-J17,N17-J17) -> 11 | P17: 44674 | Q17: 44665 | R17: 44674 | S17: =IF(ISBLANK(R17)=TRUE,TODAY()-J17,R17-J17) -> 36 | T17: 44679 | X17: 22-0029-204 | AA17: rebooked by Carrier ex Seamax Fairfield / etd 14.04.2022
A18: Eich | B18: TSL/48433/4407993146 | C18: EXW | D18: HAM | E18: CCU | F18: 1 pcs | G18: 362 | H18: 0.226 | I18: Northern Justice | J18: 44648 | K18: 44650 | M18: 44651 | N18: 44656 | O18: =IF(ISBLANK(N18)=TRUE,TODAY()-J18,N18-J18) -> 8 | P18: 44674 | Q18: 44665 | R18: 44674 | S18: =IF(ISBLANK(R18)=TRUE,TODAY()-J18,R18-J18) -> 26 | T18: 44679 | X18: 22-0030-204 | AA18: rebooked by Carrier ex Seamax Fairfield / etd 14.04.2022
A19: PWL | B19: TSL/49050/2200048660 | C19: FOB | D19: HAM | E19: CCU | F19: 1 pcs | G19: 255 | H19: 1.232 | I19: Northern Justice | J19: 44643 | K19: 44649 | N19: 44657 | O19: =IF(ISBLANK(N19)=TRUE,TODAY()-J19,N19-J19) -> 14 | P19: 44674 | Q19: 44665 | R19: 44674 | S19: =IF(ISBLANK(R19)=TRUE,TODAY()-J19,R19-J19) -> 31 | T19: 44679 | X19: 22-0031-204 | AA19: rebooked by Carrier ex Seamax Fairfield / etd 14.04.2022
A20: PWL | B20: TSL/47933/2200047402 | C20: FOB | D20: HAM | E20: CCU | F20: 3 pcs | G20: 4080 | H20: 19.618 | I20: Northern Justice | J20: 44643 | K20: 44651 | N20: 44659 | O20: =IF(ISBLANK(N20)=TRUE,TODAY()-J20,N20-J20) -> 16 | P20: 44674 | Q20: 44665 | R20: 44674 | S20: =IF(ISBLANK(R20)=TRUE,TODAY()-J20,R20-J20) -> 31 | T20: 44679 | X20: 22-0032-204 | AA20: rebooked by Carrier ex Seamax Fairfield / etd 14.04.2022
A21: SIJ Ravne | B21: TSL/49077/2200048712 | C21: EXW | D21: HAM | E21: CCU | F21: 2 pcs | G21: 372 | H21: 0.14 | I21: Northern Justice | J21: 44650 | K21: 44652 | M21: 44656 | N21: 44659 | O21: =IF(ISBLANK(N21)=TRUE,TODAY()-J21,N21-J21) -> 9 | P21: 44674 | Q21: 44665 | R21: 44674 | S21: =IF(ISBLANK(R21)=TRUE,TODAY()-J21,R21-J21) -> 24 | T21: 44679 | X21: 22-0033-204 | AA21: rebooked by Carrier ex Seamax Fairfield / etd 14.04.2022
A22: Sibre | B22: TSL/48764/3700843744 | C22: FOB | D22: HAM | E22: CCU | F22: 2 pcs | G22: 712 | H22: 1.966 | I22: Northern Justice | J22: 44657 | K22: 44658 | M22: 44659 | N22: 44662 | O22: =IF(ISBLANK(N22)=TRUE,TODAY()-J22,N22-J22) -> 5 | P22: 44674 | Q22: 44665 | R22: 44674 | S22: =IF(ISBLANK(R22)=TRUE,TODAY()-J22,R22-J22) -> 17 | T22: 44679 | X22: 22-0034-204 | AA22: rebooked by Carrier ex Seamax Fairfield / etd 14.04.2022
A23: Sibre | B23: TSL/49260/3700850109 | C23: FOB | D23: HAM | E23: CCU | F23: 4 pcs | G23: 1227 | H23: 3.362 | I23: Northern Justice | J23: 44657 | K23: 44658 | M23: 44659 | N23: 44662 | O23: =IF(ISBLANK(N23)=TRUE,TODAY()-J23,N23-J23) -> 5 | P23: 44674 | Q23: 44665 | R23: 44674 | S23: =IF(ISBLANK(R23)=TRUE,TODAY()-J23,R23-J23) -> 17 | T23: 44679 | X23: 22-0035-204 | AA23: rebooked by Carrier ex Seamax Fairfield / etd 14.04.2022
A24: Atlantic | B24: TBD/2212/2200049018 | C24: FOB | D24: HAM | E24: CCU | F24: 5 pcs | G24: 1354 | H24: 2.555 | I24: Northern Justice | J24: 44656 | K24: 44656 | M24: 44659 | N24: 44663 | O24: =IF(ISBLANK(N24)=TRUE,TODAY()-J24,N24-J24) -> 7 | P24: 44674 | Q24: 44665 | R24: 44674 | S24: =IF(ISBLANK(R24)=TRUE,TODAY()-J24,R24-J24) -> 18 | T24: 44679 | X24: 22-0036-204-00 | AA24: rebooked by Carrier ex Seamax Fairfield / etd 14.04.2022
A25: Cavex | B25: TSL/48719/2200048435 | C25: FOB | D25: HAM | E25: CCU | F25: 1 pcs | G25: 378 | H25: 0.892 | I25: Northern Justice | J25: 44656 | K25: 44658 | M25: 44659 | N25: 44663 | O25: =IF(ISBLANK(N25)=TRUE,TODAY()-J25,N25-J25) -> 7 | P25: 44674 | Q25: 44665 | R25: 44674 | S25: =IF(ISBLANK(R25)=TRUE,TODAY()-J25,R25-J25) -> 18 | T25: 44679 | X25: 22-0037-204 | AA25: rebooked by Carrier ex Seamax Fairfield / etd 14.04.2022
A26: Metso | B26: TSL/48600/2200048120 | C26: EXW | D26: HAM | E26: CCU | F26: 1 pcs | G26: 1056 | H26: 1.386 | I26: Northern Justice | J26: 44650 | K26: 44652 | M26: 44655 | N26: 44662 | O26: =IF(ISBLANK(N26)=TRUE,TODAY()-J26,N26-J26) -> 12 | P26: 44674 | Q26: 44665 | R26: 44674 | S26: =IF(ISBLANK(R26)=TRUE,TODAY()-J26,R26-J26) -> 24 | T26: 44679 | X26: 22-0038-204 | AA26: rebooked by Carrier ex Seamax Fairfield / etd 14.04.2022
A27: Malmedie | B27: TSL/49398/3700851022 | C27: FOB | D27: HAM | E27: CCU | F27: 1 pcs | G27: 730 | H27: 0.632 | I27: Northern Justice | J27: 44659 | K27: 44662 | N27: 44664 | O27: =IF(ISBLANK(N27)=TRUE,TODAY()-J27,N27-J27) -> 5 | P27: 44674 | Q27: 44671 | R27: 44674 | S27: =IF(ISBLANK(R27)=TRUE,TODAY()-J27,R27-J27) -> 15 | T27: 44679 | X27: 22-0039-204 | AA27: vessel delayed
A28: Binder | B28: TSL/49633/2200049723 | C28: EXW | D28: HAM | E28: CCU | F28: 2 pcs | G28: 266 | H28: 1.747 | I28: Northern Justice | J28: 44657 | K28: 44658 | M28: 44662 | N28: 44665 | O28: =IF(ISBLANK(N28)=TRUE,TODAY()-J28,N28-J28) -> 8 | P28: 44674 | Q28: 44671 | R28: 44674 | S28: =IF(ISBLANK(R28)=TRUE,TODAY()-J28,R28-J28) -> 17 | T28: 44679 | X28: 22-0040-204 | AA28: vessel delayed
A29: Sarclad | B29: TICRC/1570/2200049378 | C29: EXW | D29: LON | E29: NSA | F29: 1 pcs | G29: 836 | H29: 2.278 | I29: MSC Azov | J29: 44637 | K29: 44641 | M29: 44641 | N29: 44644 | O29: =IF(ISBLANK(N29)=TRUE,TODAY()-J29,N29-J29) -> 7 | P29: 44669 | Q29: 44655 | R29: 44669 | S29: =IF(ISBLANK(R29)=TRUE,TODAY()-J29,R29-J29) -> 32 | T29: 44680 | AA29: vessel delayed
A30: Fosbel | B30: TSL/2200048968 | C30: FOB | D30: NYC | E30: CCU | F30: 3 pcs | G30: 3205 | H30: 3.398 | I30: YM Width | J30: 44615 | K30: 44615 | N30: 44624 | O30: =IF(ISBLANK(N30)=TRUE,TODAY()-J30,N30-J30) -> 9 | P30: 44655 | Q30: 44630 | R30: 44655 | S30: =IF(ISBLANK(R30)=TRUE,TODAY()-J30,R30-J30) -> 40 | T30: 44671 | X30: 22-0042-204 | AA30: vessel delayed by carrier / delay on paperwork by supplier
A31: Irizar | B31: TSL/48578/2200048263 | C31: FOB | D31: BIO | E31: CCU | F31: 1 pcs | G31: 341 | H31: 0.516 | I31: Al Nasriyah | J31: 44634 | K31: 44641 | N31: 44665 | O31: =IF(ISBLANK(N31)=TRUE,TODAY()-J31,N31-J31) -> 31 | P31: 44691 | Q31: 44657 | R31: 44661 | S31: =IF(ISBLANK(R31)=TRUE,TODAY()-J31,R31-J31) -> 27 | X31: 22-0001-205 | AA31: Supplier missed the closing on 26.03.2022 // Vsl delayed
A32: Irizar | B32: TSL/45072/2200043417 | C32: FOB | D32: BIO | E32: CCU | F32: 1 pcs | G32: 683 | H32: 0.637 | I32: Al Nasriyah | J32: 44637 | K32: 44641 | N32: 44665 | O32: =IF(ISBLANK(N32)=TRUE,TODAY()-J32,N32-J32) -> 28 | P32: 44691 | Q32: 44657 | R32: 44661 | S32: =IF(ISBLANK(R32)=TRUE,TODAY()-J32,R32-J32) -> 24 | X32: 22-0002-205 | AA32: Supplier missed the closing on 26.03.2022 // Vsl delayed
A33: Irizar | B33: TSL/47442/2200045643 | C33: FOB | D33: BIO | E33: CCU | F33: 1 pcs | G33: 680 | H33: 0.714 | I33: Al Nasriyah | J33: 44664 | K33: 44641 | N33: 44678 | O33: =IF(ISBLANK(N33)=TRUE,TODAY()-J33,N33-J33) -> 14 | P33: 44691 | Q33: 44679 | R33: 44661 | S33: =IF(ISBLANK(R33)=TRUE,TODAY()-J33,R33-J33) -> -3 | X33: 22-0003-205 | AA33: Vessel delayed
A34: Irizar | B34: TSL/48876/2200048476 | C34: FOB | D34: BIO | E34: CCU | F34: 2 pcs | G34: 1485 | H34: 1.855 | I34: Al Nasriyah | J34: 44671 | K34: 44672 | N34: 44679 | O34: =IF(ISBLANK(N34)=TRUE,TODAY()-J34,N34-J34) -> 8 | P34: 44691 | Q34: 44685 | R34: 44661 | S34: =IF(ISBLANK(R34)=TRUE,TODAY()-J34,R34-J34) -> -10 | X34: 22-0004-205 | AA34: Vessel Delayed
A35: Metal 7 | B35: TSL/48684/2200048372 | C35: FCA | D35: MTR | E35: CCU | F35: 1 pcs | G35: 335.6 | H35: 0.59 | I35: YM Truth | J35: 44599 | K35: 44630 | M35: 44630 | N35: 44644 | O35: =IF(ISBLANK(N35)=TRUE,TODAY()-J35,N35-J35) -> 45 | P35: 44675 | Q35: 44650 | R35: 44675 | S35: =IF(ISBLANK(R35)=TRUE,TODAY()-J35,R35-J35) -> 76 | AA35: Vessel Delayed at origin
A36: Metal 7 | B36: TSL/48683/22000483721 | C36: FCA | D36: MTR | E36: CCU | F36: 5 pcs | G36: 5075 | H36: 7.95 | I36: YM Truth | J36: 44628 | K36: 44630 | M36: 44630 | N36: 44644 | O36: =IF(ISBLANK(N36)=TRUE,TODAY()-J36,N36-J36) -> 16 | P36: 44675 | Q36: 44650 | R36: 44675 | S36: =IF(ISBLANK(R36)=TRUE,TODAY()-J36,R36-J36) -> 47 | AA36: Vessel Delayed at origin
A37: Metal 7 | B37: TSL/48686/2200048365 | C37: FCA | D37: MTR | E37: CCU | F37: 1 pcs | G37: 254 | H37: 0.562 | I37: YM Truth | J37: 44629 | K37: 44630 | M37: 44630 | N37: 44644 | O37: =IF(ISBLANK(N37)=TRUE,TODAY()-J37,N37-J37) -> 15 | P37: 44675 | Q37: 44650 | R37: 44675 | S37: =IF(ISBLANK(R37)=TRUE,TODAY()-J37,R37-J37) -> 46 | AA37: Vessel Delayed at origin
A38: Tallmann | B38: TSL/48748/2200048291 | C38: EXW | D38: TOR | E38: CCU | F38: 2 pcs | G38: 1182 | H38: 1.024 | I38: MSC Valeria | J38: 44631 | K38: 44635 | M38: 44635 | N38: 44636 | O38: =IF(ISBLANK(N38)=TRUE,TODAY()-J38,N38-J38) -> 5 | P38: 44673 | Q38: 44641 | R38: 44673 | S38: =IF(ISBLANK(R38)=TRUE,TODAY()-J38,R38-J38) -> 42 | AA38: Vessel Delayed at origin
A39: Kadant Johnson | B39: TSL/49109/4408511872 | C39: EXW | D39: RTM | E39: CCU | F39: 1 pcs | G39: 267.5 | H39: 0.844 | I39: MSC Irene | J39: 44662 | K39: 44664 | M39: 44665 | N39: 44670 | O39: =IF(ISBLANK(N39)=TRUE,TODAY()-J39,N39-J39) -> 8 | P39: 44688 | Q39: 44679 | R39: 44687 | S39: =IF(ISBLANK(R39)=TRUE,TODAY()-J39,R39-J39) -> 25 | AA39: rebooked by Carrier ex Seamax Fairfield / etd 28.04.2022
A40: ASA Drilling | B40: TSL/49366/2200049228 | C40: EXW | D40: TOR | E40: CCU | F40: 1 pcs | G40: 517 | H40: 0.711 | I40: Maersk Yukon | J40: 44636 | K40: 44655 | M40: 44657 | N40: 44662 | O40: =IF(ISBLANK(N40)=TRUE,TODAY()-J40,N40-J40) -> 26 | P40: 44673 | Q40: 44667 | R40: 44673 | S40: =IF(ISBLANK(R40)=TRUE,TODAY()-J40,R40-J40) -> 37 | AA40: Vessel Delayed at origin
...

Sheet Useful
C2: EXIT CUSTOMS CODE HAMBURG= DE/004851
C5: CUSTOMS EXIT - Barcelona / code : ES000812
H7: Cnee/Notify | M7: TATA Steel Ltd
C8: Shipper: | F8: Cnee/Notify | H8: TKM GLOBAL LOGISTICS LTD | M8: IEC Code: 0388039124
C9: TKM Global GmbH | F9: TKM Global Logistics Ltd | H9: EVEREST CHAMBER, B-206, MATHURADAS VASANJI RD,
C10: Esplanade 41 | F10: Infinity IT Lagoon | H10: NEAR MAROL METRO STATION, ANDHER EAST,
C11: 20354 Hamburg, Germany | F11: 7th Floor, Sector V, Bidhannagar | H11: MUMBAI- 400059, MAHARASHTRA, INDIA | M11: TKM Global GmbH
F12: 700091 Kolkata, India | H12: PAN: AABCT2426M | M12: EORI: DE3236978
F13: GST 19AABCT2426M1Z4 | H13: GST: 27AABCT2426M1Z7
F14: PAN: AABCT2426M | H14: Janhavi@tkmglobal.com
F15: TKMCCU@TkmGlobal.com | H15: CELL: +91 9833407164
F16: CONTACT: PARTHA DAS +91 98311 17122
C17: Freight Prepaid | F17: PARTHA@TKMGLOBAL.COM
C18: Express B/L
H19: 1.ONE ORPHEUS 075W=ETD-08.12.25
C20: Marks: | D20: 5 cases | F20: 99.344KGS | G20: 19,984cbm | H20: 2.ONE HAMBURG / 083W=ETD- 18.11.25
C21: TATA Steel Limited | F21: s.t.c. | H21: 3.ONE OLYMPUS / 079W=ETD-24.12.25
C22: TSL/49567/2200049440 | F22: 1 Set Spare
F23: Pressurization Valve, Hot Stove
F24: Inv.: 37001608
F25: HS-Code: 84818085
C26: Marks: | D26: 2 cases | F26: 1540,0KGS | G26: 3,063cbm
C27: Jindal Steel & Power Ltd | F27: s.t.c.
C28: 4561104547 | F28: Supply of Lance Tips as per
F29: PO NO: 4561104547 DTD 03.09.2022
F30: TERMS CIF Kolkata Seaport in India
F31: Incoterms 2020
F32: HS-Code: 84179000
C33: Marks: | D33: 7 cases | F33: 11.080,0KGS | G33: 11,660cbm
C34: TATA Steel Limited | F34: s.t.c.
C35: TSL/49463/2200049473 | F35: Bearing Retainer
F36: Sleeving Ring Unit
F37: Sleeve Unit
F38: Inv.: 60171691 + 60171689
F39: HS-Code: 84559000
C40: Marks: | D40: 1 case | F40: 153,0KGS | G40: 0,384cbm
C41: TATA Steel Limited | F41: s.t.c.
C42: TSL/49787/2200050004 | F42: Universal Compensator DN 200
F43: Inv.: 260147
F44: HS-Code: 83071000
